from odoo import models, fields, api
import logging

_logger = logging.getLogger(__name__)


class KpiHistory(models.Model):
    _name = 'kpi.history'
    _description = 'KPI Activity History Log'
    _order = 'activity_date desc, id desc'

    target_id = fields.Many2one('kpi.target', string='KPI Target', required=True, ondelete='cascade')
    target_line_id = fields.Many2one('kpi.target.line', string='KPI Target Line', readonly=True)
    kpi_definition_id = fields.Many2one('kpi.definition', string='KPI Definition', readonly=True)

    source_document_model = fields.Char(string='Source Model', readonly=True)
    source_document_id = fields.Integer(string='Source ID', readonly=True)
    source_document = fields.Reference(
        selection='_get_source_document_models',
        string='Source Document',
        compute='_compute_source_document',
        readonly=True
    )

    activity_date = fields.Datetime(string='Activity Date', readonly=True)
    description = fields.Text(string='Description', readonly=True)
    data_quality_score = fields.Float(string='Data Quality Score', digits=(5, 2), readonly=True)
    data_quality_type = fields.Selection([
        ('name_confirmed', 'Name Confirmed'),
        ('address_confirmed', 'Address Confirmed'),
        ('phone_confirmed', 'Phone Confirmed'),
        ('service_satisfaction_confirmed', 'Service Satisfaction Confirmed'),
        ('product_information_confirmed', 'Product Information Confirmed'),
        ('all_confirmations', 'All Confirmations'),  # <-- NEW: This fixes the ValueError
    ], string='Data Quality Type', help="Which data quality metric this record is related to.")
    # User fields for easy reporting
    user_id = fields.Many2one(related='target_id.user_id', store=True, string='User')

    # Field to display data quality type
    display_data_quality_type = fields.Char(
        string='Quality Type',
        compute='_compute_display_data_quality_type'
    )

    def _get_source_document_models(self):
        """Define the models that can be referenced as source documents."""
        # ðŸ’¡ FIX: Removed 'telemarketing.confirmation' from the list of valid models.
        return [
            ('crm.lead', 'Lead/Opportunity'),
            ('crm.phonecall', 'Phone Call'),
        ]

    def _compute_source_document(self):
        """
        Compute the reference field.
        This includes a fix to handle KeyError for old records pointing to the
        deleted 'telemarketing.confirmation' model.
        """
        for rec in self:
            if rec.source_document_model and rec.source_document_id:
                try:
                    # Attempt to browse the model.
                    rec.source_document = self.env[rec.source_document_model].browse(rec.source_document_id)
                except KeyError:
                    # ðŸ’¡ FIX: Gracefully handle records pointing to a deleted model.
                    _logger.warning(
                        f"KPI History Record {rec.id} references non-existent model: {rec.source_document_model}"
                    )
                    rec.source_document = False
            else:
                rec.source_document = False

    @api.depends('data_quality_type')
    def _compute_display_data_quality_type(self):
        """Convert selection value to display-friendly format"""
        type_mapping = {
            'name_confirmed': 'Name',
            'address_confirmed': 'Address',
            'phone_confirmed': 'Phone',
            'service_satisfaction_confirmed': 'Service',
            'product_information_confirmed': 'Product',
            'all_confirmations': 'All',
        }
        for rec in self:
            if rec.data_quality_type:
                # Use .get() with the original value as a fallback for safety
                rec.display_data_quality_type = type_mapping.get(rec.data_quality_type, rec.data_quality_type)
            else:
                rec.display_data_quality_type = False